Workbook

Sheet Veiledning
A1: IPR kurs – kartlegging og gevinstvurdering
A2: Arbeidsbok til kartleggingsmøtet med administrasjonen. Fylles ut i møtet og etterpå.
A4: Slik brukes arket
A5: Gul celle | B5: Fylles inn av dere. Alt annet regnes ut automatisk.
A6: Grå celle | B6: Forslag fra Jan/Claude (f.eks. forventet automatiseringsgrad). Overstyr i gul kolonne ved siden av.
A7: Blå tekst | B7: Antakelse / fast tall som kan endres (f.eks. timekost).
A9: Arkfaner
A10: Møteplan | B10: Agenda og tidsbruk for møtet.
A11: Prosess | B11: HOVEDARK. Hva gjøres i dag, hvor ofte, hvor lang tid – og hvor mye kan automatiseres. Gir timer spart.
A12: Kurstyper | B12: Volum: hvilke kurs, hvor mange, hvordan de faktureres. Brukes til å anslå frekvenser i Prosess.
A13: Funksjoner | B13: Pindena-funksjoner og nye ønsker. Marker hva som brukes i dag og hva som er Må/Bør/Kan.
A14: Integrasjoner | B14: Visma, SharePoint, e-post, Zoom, nettside … hva brukes, hvem eier, hva må avklares.
A15: IT og drift | B15: Spørsmål til IT-tjenesten før bestilling.
A16: Gevinst | B16: Oppsummering: timer spart per område, kroner, og sammenligning med dagens kostnad.
A18: Eksempel (Prosess-arket)
A19: Steg | B19: Sende bekreftelse på påmelding
A20: Hvordan i dag | B20: Pindena sender automatisk, men adm sjekker og svarer manuelt på ca. 1 av 5
A21: Antall per år | B21: 400 (≈ antall påmeldinger)
A22: Minutter per gang | B22: 2 (gjennomsnitt, inkl. de som ikke krever noe)
A23: Automatiseringsgrad | B23: 100 % → 400 × 2 / 60 = 13,3 timer spart per år
A24: Smertepunkt | B24: Folk svarer på bekreftelsen med spørsmål som havner i adm sin innboks
A26: Tips
A27: Anslag holder | B27: Grove tall er bedre enn ingen tall. «10–15 minutter, ca. 30 ganger i året» er godt nok. Skriv usikkerhet i kommentarfeltet.

Sheet Møteplan
A1: Møteplan – kartlegging av kursadministrasjon
A2: Ca. 2 timer. Deltakere: Jan + adm. Se også «Kartleggingsmøte – opplegg» (Word/markdown).
A4: Nr | B4: Tema | C4: Min | D4: Mål / hva vi fyller ut | E4: Ark
A5: 0 | B5: Rammer og mål | C5: 10 | D5: Hvorfor vi gjør dette, hva som skal ut av møtet, at ingenting er bestemt ennå. | E5: –
A6: 1 | B6: Følg ett kurs fra idé til avsluttet | C6: 35 | D6: Gå gjennom et konkret, nylig kurs steg for steg. Hva gjøres, i hvilket verktøy, hvor lang tid, hva irriterer. | E6: Prosess
A7: 2 | B7: Kurstyper og volum | C7: 10 | D7: Hvilke kursformer finnes, antall per år, deltakere, fakturering per person/samlet. | E7: Kurstyper
A8: 3 | B8: Funksjoner – bruk og behov | C8: 20 | D8: Hva brukes i Pindena i dag, hva savnes, hva er Må/Bør/Kan. | E8: Funksjoner
A9: 4 | B9: Demo av prototypen | C9: 15 | D9: Vis påmelding → bekreftelse → faktura → QR-innsjekk → Min side → admin. Noter reaksjoner. | E9: Funksjoner (kommentar)
A10: 5 | B10: Integrasjoner og IT | C10: 15 | D10: Visma-produkt, SharePoint-struktur, e-postkonto, Zoom, nettside. Hvem i IT kontaktes? | E10: Integrasjoner, IT og drift
A11: 6 | B11: Rolle: vedlikehold med Claude Code | C11: 10 | D11: Interesse, tid per uke, opplæringsbehov, hvem er backup. | E11: –
A12: 7 | B12: Grov gevinst og neste steg | C12: 10 | D12: Se over gevinstarket. Avtal hvem fyller ut resten, frist, og neste møte. | E12: Gevinst
B13: Totalt | C13: =SUM(C5:C12)

Sheet Prosess
A1: Prosesskartlegging – slik gjøres det i dag
A2: Fyll inn gule kolonner. Timer/år og timer spart regnes automatisk. Automatiseringsgrad: grå = forslag, gul = deres vurdering (overstyrer).
A4: Område | B4: Steg | C4: Hvordan i dag (verktøy, hvem) | D4: Hvem gjør det | E4: Antall per år | F4: Min per gang | G4: Timer per år | H4: Forslag autom. | I4: Deres autom. | J4: Timer spart/år | K4: Løses i prototypen? | L4: Smertepunkt / kommentar | M4: Prioritet
A5: Kursoppsett | B5: Opprette kurs (datoer, pris, sted, kapasitet) | G5: =IF(AND(ISNUMBER(E5),ISNUMBER(F5)),E5*F5/60,0) | H5: 0.5 | J5: =G5*IF(ISNUMBER(I5),I5,IF(ISNUMBER(H5),H5,0)) | K5: Ja
A6: Kursoppsett | B6: Publisere kurs og påmeldingsskjema på nettsiden | G6: =IF(AND(ISNUMBER(E6),ISNUMBER(F6)),E6*F6/60,0) | H6: 0.75 | J6: =G6*IF(ISNUMBER(I6),I6,IF(ISNUMBER(H6),H6,0)) | K6: Ja
A7: Kursoppsett | B7: Bestille lokale og catering | G7: =IF(AND(ISNUMBER(E7),ISNUMBER(F7)),E7*F7/60,0) | H7: 0.25 | J7: =G7*IF(ISNUMBER(I7),I7,IF(ISNUMBER(H7),H7,0)) | K7: Nei
A8: Kursoppsett | B8: Avtale med kursholder (oppdrag, honorar) | G8: =IF(AND(ISNUMBER(E8),ISNUMBER(F8)),E8*F8/60,0) | H8: 0.25 | J8: =G8*IF(ISNUMBER(I8),I8,IF(ISNUMBER(H8),H8,0)) | K8: Nei
A9: Påmelding | B9: Motta og registrere påmeldinger | G9: =IF(AND(ISNUMBER(E9),ISNUMBER(F9)),E9*F9/60,0) | H9: 1 | J9: =G9*IF(ISNUMBER(I9),I9,IF(ISNUMBER(H9),H9,0)) | K9: Ja
A10: Påmelding | B10: Svare på spørsmål før påmelding | G10: =IF(AND(ISNUMBER(E10),ISNUMBER(F10)),E10*F10/60,0) | H10: 0.5 | J10: =G10*IF(ISNUMBER(I10),I10,IF(ISNUMBER(H10),H10,0)) | K10: Delvis
A11: Påmelding | B11: Håndtere venteliste | G11: =IF(AND(ISNUMBER(E11),ISNUMBER(F11)),E11*F11/60,0) | H11: 1 | J11: =G11*IF(ISNUMBER(I11),I11,IF(ISNUMBER(H11),H11,0)) | K11: Ja
A12: Påmelding | B12: Avmeldinger og endringer | G12: =IF(AND(ISNUMBER(E12),ISNUMBER(F12)),E12*F12/60,0) | H12: 0.75 | J12: =G12*IF(ISNUMBER(I12),I12,IF(ISNUMBER(H12),H12,0)) | K12: Delvis
A13: Påmelding | B13: Sende bekreftelse | G13: =IF(AND(ISNUMBER(E13),ISNUMBER(F13)),E13*F13/60,0) | H13: 1 | J13: =G13*IF(ISNUMBER(I13),I13,IF(ISNUMBER(H13),H13,0)) | K13: Ja
A14: Fakturering | B14: Opprette faktura per deltaker | G14: =IF(AND(ISNUMBER(E14),ISNUMBER(F14)),E14*F14/60,0) | H14: 1 | J14: =G14*IF(ISNUMBER(I14),I14,IF(ISNUMBER(H14),H14,0)) | K14: Ja
A15: Fakturering | B15: Samlefaktura til organisasjon | G15: =IF(AND(ISNUMBER(E15),ISNUMBER(F15)),E15*F15/60,0) | H15: 0.5 | J15: =G15*IF(ISNUMBER(I15),I15,IF(ISNUMBER(H15),H15,0)) | K15: Nei
A16: Fakturering | B16: Kreditnota ved avmelding | G16: =IF(AND(ISNUMBER(E16),ISNUMBER(F16)),E16*F16/60,0) | H16: 0.5 | J16: =G16*IF(ISNUMBER(I16),I16,IF(ISNUMBER(H16),H16,0)) | K16: Nei
... A35: Etterarbeid | B35: Arkivering og sletting av personopplysninger | G35: =IF(AND(ISNUMBER(E35),ISNUMBER(F35)),E35*F35/60,0) | H35: 0.75 | J35: =G35*IF(ISNUMBER(I35),I35,IF(ISNUMBER(H35),H35,0)) | K35: Delvis
G36: =IF(AND(ISNUMBER(E36),ISNUMBER(F36)),E36*F36/60,0) | J36: =G36*IF(ISNUMBER(I36),I36,IF(ISNUMBER(H36),H36,0))
G37: =IF(AND(ISNUMBER(E37),ISNUMBER(F37)),E37*F37/60,0) | J37: =G37*IF(ISNUMBER(I37),I37,IF(ISNUMBER(H37),H37,0))
G38: =IF(AND(ISNUMBER(E38),ISNUMBER(F38)),E38*F38/60,0) | J38: =G38*IF(ISNUMBER(I38),I38,IF(ISNUMBER(H38),H38,0))
G39: =IF(AND(ISNUMBER(E39),ISNUMBER(F39)),E39*F39/60,0) | J39: =G39*IF(ISNUMBER(I39),I39,IF(ISNUMBER(H39),H39,0))
G40: =IF(AND(ISNUMBER(E40),ISNUMBER(F40)),E40*F40/60,0) | J40: =G40*IF(ISNUMBER(I40),I40,IF(ISNUMBER(H40),H40,0))
G41: =IF(AND(ISNUMBER(E41),ISNUMBER(F41)),E41*F41/60,0) | J41: =G41*IF(ISNUMBER(I41),I41,IF(ISNUMBER(H41),H41,0))
B42: Totalt | G42: =SUM(G5:G41) | H42: =IF(G42>0,J42/G42,0) | J42: =SUM(J5:J41)

Sheet Kurstyper
A1: Kurstyper og volum
A2: Én rad per kurstype. Tallene brukes til å anslå «Antall per år» i Prosess-arket.
A4: Kurstype | B4: Kurs per år | C4: Deltakere per kurs | D4: Kursdager per kurs | E4: Format | F4: Fakturering | G4: Pris (kr) | H4: Særlige behov
A5: EFT spesialistutdanning (samlinger)
A6: Digitale enkeltstående kurs
A7: Bedriftsinterne kurs
A12: Totalt / sum | B12: =SUM(B5:B11) | C12: =SUMPRODUCT(B5:B11,C5:C11) | D12: =SUMPRODUCT(B5:B11,D5:D11)
B13: kurs/år | C13: påmeldinger/år | D13: kursdager/år

Sheet Funksjoner
A1: Funksjoner – bruk i dag og behov framover
A2: «Brukes i dag» og «Behov» fylles ut i møtet. «I prototypen» viser hva som finnes allerede.
A4: ID | B4: Område | C4: Funksjon | D4: Beskrivelse | E4: Brukes i dag? | F4: Behov | G4: I prototypen | H4: Kommentar
A5: F01 | B5: Påmelding | C5: Påmeldingsskjema på nettsiden | D5: Skjema per kurs, egne felt per kurstype | G5: Ja
A6: F02 | B6: Påmelding | C6: Kursoversikt / kalender | D6: Liste over åpne kurs, innbygget på ipr-nettsiden | G6: Delvis
A7: F03 | B7: Påmelding | C7: Venteliste med automatisk opprykk | D7: Fullt kurs → venteliste → plass ved avmelding | G7: Ja
A8: F04 | B8: Påmelding | C8: Rabattkoder / medlemspris | D8: Ulike priser for grupper, tidlig påmelding | G8: Nei
A9: F05 | B9: Påmelding | C9: Betaling med kort/Vipps ved påmelding | D9: Alternativ til faktura | G9: Nei
A10: F06 | B10: Påmelding | C10: Påmelding av flere deltakere samtidig | D10: Arbeidsgiver melder på flere ansatte | G10: Nei
A11: F07 | B11: Påmelding | C11: Selvbetjent avmelding | D11: Deltaker melder seg av selv innen frist | G11: Nei
A12: F08 | B12: Påmelding | C12: Vilkår og samtykke | D12: Aksept av vilkår og personvern lagres | G12: Ja
A13: F09 | B13: Faktura | C13: Automatisk faktura per deltaker til Visma | D13: Opprettes ved påmelding | G13: Ja
A14: F10 | B14: Faktura | C14: Faktura til arbeidsgiver / EHF | D14: Org.nr, referanse, EHF | G14: Ja
A15: F11 | B15: Faktura | C15: Samlefaktura per organisasjon | D15: Én faktura for flere deltakere | G15: Nei
A16: F12 | B16: Faktura | C16: Delbetaling / avdrag (spesialistløp) | D16: Faktura per semester/samling | G16: Nei
... A18: F14 | B18: Faktura | C18: Betalingsstatus tilbake fra Visma | D18: Se hvem som har betalt | G18: Nei
A19: F15 | B19: E-post | C19: Bekreftelse ved påmelding | G19: Ja
A20: F16 | B20: E-post | C20: Velkomst/praktisk info uka før | G20: Ja
A21: F17 | B21: E-post | C21: Påminnelse + Zoom-lenke dagen før | G21: Ja
A22: F18 | B22: E-post | C22: Manuell utsending til alle på et kurs | D22: Endringer, avlysning | G22: Nei
A23: F19 | B23: E-post | C23: SMS-påminnelser | G23: Nei
A24: F20 | B24: E-post | C24: Redigerbare e-postmaler | D24: Adm endrer tekst selv | G24: Delvis
A25: F21 | B25: Min side | C25: Innlogging uten passord (e-postlenke) | D25: Evt. BankID / Feide / Microsoft | G25: Ja
A26: F22 | B26: Min side | C26: Oversikt over egne kurs og oppmøte | G26: Ja
A27: F23 | B27: Min side | C27: Kursmateriell (presentasjoner) | D27: Fra SharePoint, kun for påmeldte | G27: Ja
A28: F24 | B28: Min side | C28: Kontrakter og personlige dokumenter | D28: Utdanningskontrakt o.l. | G28: Ja
A29: F25 | B29: Min side | C29: Kursbevis og timeoversikt spesialistløp | G29: Ja
A30: F26 | B30: Min side | C30: Fakturaer og betalingsstatus | G30: Delvis
A31: F27 | B31: Min side | C31: Oppdatere egen kontaktinfo | G31: Nei
A32: F28 | B32: Min side | C32: Digital signering av kontrakt | D32: F.eks. via Visma Sign / Signicat | G32: Nei
A33: F29 | B33: Oppmøte | C33: QR-innsjekk i kurslokalet | D33: Skann kode på skjerm | G33: Ja
A34: F30 | B34: Oppmøte | C34: Innsjekk med kode (uten QR) | G34: Ja
A35: F31 | B35: Oppmøte | C35: Oppmøte fra Zoom automatisk | G35: Ja
A36: F32 | B36: Oppmøte | C36: Manuell registrering/korrigering | G36: Ja
A37: F33 | B37: Oppmøte | C37: Varsel ved fravær | D37: Til deltaker og/eller adm | G37: Nei
A38: F34 | B38: Kursholder | C38: Purring på presentasjoner | D38: Automatisk før frist, eskalering til adm | G38: Ja
A39: F35 | B39: Kursholder | C39: Opplasting av materiell | G39: Ja
A40: F36 | B40: Kursholder | C40: Deltakerliste til kursholder | G40: Nei
A41: F37 | B41: Gjennomføring | C41: Allergi-/tilretteleggingsliste | D41: Sensitivt – slettes etter kurs | G41: Ja
A42: F38 | B42: Gjennomføring | C42: Navneskilt / deltakerliste for utskrift | G42: Delvis
...

Sheet Integrasjoner
A1: Integrasjoner
A2: Hva systemet må snakke med. Gule felt fylles inn.
A4: System | B4: Brukes til | C4: Produkt / versjon | D4: Eier / kontakt | E4: API-tilgang? | F4: Må avklares | G4: Svar
A5: Visma | B5: Kunder og fakturaer, betalingsstatus | F5: Hvilket Visma-produkt? (eAccounting/eRegnskap, Visma.net, Business NXT …) Har vi API-lisens? Artikkelnumre per kurstype? Hvem fører regnskapet (internt/regnskapsbyrå)?
A6: SharePoint | B6: Kursmateriell, kontrakter, arkiv | F6: Hvilken site/bibliotek? Dagens mappestruktur? Hvem skal ha tilgang? Oppbevaringstid?
A7: E-post (M365) | B7: Utsending til deltakere, svar fra deltakere | F7: Egen kurspostboks (f.eks. kurs@)? Delt postboks? Hvor havner svar? Signatur/avsendernavn?
A8: Zoom / Teams | B8: Digitale kursdager, oppmøte | F8: Zoom eller Teams? Hvilken lisens/konto? Hvem er vert?
A9: Nettside | B9: Kursoversikt, lenke til påmelding | F9: Craft CMS (byrå Bielke&Yang). Har IPR innlogging til Craft? Hvem bytter ~45 Booking-lenker? Se egen rapport.
A10: Pindena | B10: Dagens system (to kontoer: IPR og IPR Oslo) | F10: Eksport av historikk (deltakere, kurs, fakturaer, NIEFT-medlemmer)? Oppsigelsestid og kostnad per år for begge kontoer? Hva må migreres?
A11: Aspit Helse | B11: Timebestilling/journal (klienter) | F11: Utenfor kursløsningen – men bekreft at ingenting kursrelatert går via Aspit.
A12: Signering | B12: Kontrakter | F12: Brukes digital signering i dag (Visma Sign, Signicat, Adobe)?
A13: Betaling | B13: Kort/Vipps | F13: Ønskes betaling ved påmelding? Eksisterende avtale?
A14: Kalender | B14: Kursholdere | F14: Skal kursdager inn i kursholders Outlook-kalender?

Sheet IT og drift
A1: Spørsmål til IT-tjenesten
A2: Brukes som grunnlag for IT-bestillingen. Se «IT-bestilling – utkast».
A4: # | B4: Spørsmål | C4: Svar | D4: Ansvar
A5: 1 | B5: Har IPR et Azure-abonnement i dag? Hvem administrerer det?
A6: 2 | B6: Kan IT sette opp en webapp (Azure App Service / Container Apps) i region Norway East?
A7: 3 | B7: Database: Azure Database for PostgreSQL eller Azure SQL – hva foretrekker/støtter IT?
A8: 4 | B8: Kan appen få tilgang til SharePoint og e-post via Managed Identity / app-registrering (Sites.Selected, Mail.Send begrenset til kurs-postboks)?
A9: 5 | B9: Kan adm-brukere logge inn med IPR-kontoen (Entra ID) med en egen gruppe for kursadmin?
A10: 6 | B10: Hvem eier domene/DNS? Kan vi få f.eks. kurs.[domene].no med HTTPS-sertifikat?
A11: 7 | B11: Publisering: Kan vi deploye fra GitHub (GitHub Actions med OIDC) uten å gå via IT for hver endring?
A12: 8 | B12: Får vi et testmiljø i tillegg til produksjon?
A13: 9 | B13: Backup og gjenoppretting: hva er standard, og hvor lenge oppbevares backup?
A14: 10 | B14: Overvåking/varsling: hvem varsles hvis appen eller morgenjobben feiler?
A15: 11 | B15: Sikkerhet: krav til penetrasjonstest, sikkerhetsoppdateringer, logging?
A16: 12 | B16: Personvern: finnes mal for DPIA og databehandleravtaler? Hvem er personvernombud?
... A19: 15 | B19: Kan adm få installere Claude Code, Git og Python på sin PC?

Sheet Gevinst
A1: Gevinstvurdering
A2: Regnes automatisk fra Prosess-arket. Gule celler og blå tall er antakelser som kan endres.
A4: Antakelser
A5: Timekost adm inkl. sosiale kostnader (kr) | B5: 650 | E5: Antakelse – erstatt med IPRs faktiske tall
A6: Timer i ett årsverk | B6: 1650 | E6: Antakelse – vanlig tommelfingerregel
A7: Pindena lisens per år (kr) | E7: Fylles inn
A8: Drift Azure + IT-forvaltning per år (kr) | E8: Fylles inn etter svar fra IT
A9: Vedlikehold med Claude Code, timer per år | B9: 80 | E9: Antakelse – ca. 1,5 t/uke etter at systemet er i drift
A10: Claude-lisens per år (kr) | E10: Fylles inn
A11: Engangs: utvikling og innføring, timer | E11: Fylles inn – Jan + adm
A13: Tid per område (timer per år)
A14: Område | B14: I dag | C14: Spart | D14: Andel spart | E14: Kommentar
A15: Kursoppsett | B15: =SUMIFS(Prosess!$G$5:$G$41,Prosess!$A$5:$A$41,A15) | C15: =SUMIFS(Prosess!$J$5:$J$41,Prosess!$A$5:$A$41,A15) | D15: =IF(B15>0,C15/B15,0)
A16: Påmelding | B16: =SUMIFS(Prosess!$G$5:$G$41,Prosess!$A$5:$A$41,A16) | C16: =SUMIFS(Prosess!$J$5:$J$41,Prosess!$A$5:$A$41,A16) | D16: =IF(B16>0,C16/B16,0)
A17: Fakturering | B17: =SUMIFS(Prosess!$G$5:$G$41,Prosess!$A$5:$A$41,A17) | C17: =SUMIFS(Prosess!$J$5:$J$41,Prosess!$A$5:$A$41,A17) | D17: =IF(B17>0,C17/B17,0)
A18: Kommunikasjon | B18: =SUMIFS(Prosess!$G$5:$G$41,Prosess!$A$5:$A$41,A18) | C18: =SUMIFS(Prosess!$J$5:$J$41,Prosess!$A$5:$A$41,A18) | D18: =IF(B18>0,C18/B18,0)
A19: Materiell | B19: =SUMIFS(Prosess!$G$5:$G$41,Prosess!$A$5:$A$41,A19) | C19: =SUMIFS(Prosess!$J$5:$J$41,Prosess!$A$5:$A$41,A19) | D19: =IF(B19>0,C19/B19,0)
A20: Gjennomføring | B20: =SUMIFS(Prosess!$G$5:$G$41,Prosess!$A$5:$A$41,A20) | C20: =SUMIFS(Prosess!$J$5:$J$41,Prosess!$A$5:$A$41,A20) | D20: =IF(B20>0,C20/B20,0)
A21: Etterarbeid | B21: =SUMIFS(Prosess!$G$5:$G$41,Prosess!$A$5:$A$41,A21) | C21: =SUMIFS(Prosess!$J$5:$J$41,Prosess!$A$5:$A$41,A21) | D21: =IF(B21>0,C21/B21,0)
A22: Totalt | B22: =SUM(B15:B21) | C22: =SUM(C15:C21) | D22: =IF(B22>0,C22/B22,0) | E22: =IF(ABS(B22-Prosess!G42)>0.01,"Sjekk: rader i Prosess mangler område","Stemmer med Prosess-arket")
A24: Økonomi per år
A25: Timer spart per år | B25: =C22
A26: Tilsvarer årsverk | B26: =IF(B6>0,C22/B6,0)
A27: Verdi av spart tid (kr) | B27: =C22*B5
A28: + Pindena-lisens som faller bort (kr) | B28: =B7
A29: – Drift Azure/IT (kr) | B29: =-B8
A30: – Vedlikehold (kr) | B30: =-B9*B5
A31: – Claude-lisens (kr) | B31: =-B10
A32: Netto gevinst per år (kr) | B32: =SUM(B27:B31)
A33: Engangskostnad utvikling (kr) | B33: =B11*B5
A34: Tilbakebetalingstid (måneder) | B34: =IF(B32>0,B33/B32*12,"–")
A36: Ikke-økonomiske gevinster (fyll inn): færre feil, bedre deltakeropplevelse, mindre sårbarhet ved fravær, bedre personvern …
